Workbook
Name 切片器_Fiscal_year: #N/A
Name 切片器_Standard_line_item: #N/A

Sheet Cover
A1: How profitable are Canada's big three grocers? Loblaw, Metro and Empire, FY2020-FY2025
A2: An Excel analysis of six years of audited financial statements, built by Duoming Yuan (October 2026).
A4: Question | B4: Did the three big Canadian grocers earn higher margins during the 2022-2023 food inflation, and how do they compare on profitability, efficiency and cash flow?
A5: Companies | B5: Loblaw Companies (Loblaws, No Frills, Real Canadian Superstore, T&T, Shoppers Drug Mart); Metro Inc. (Metro, Food Basics, Super C, Jean Coutu); Empire Company (Sobeys, Safeway, IGA, FreshCo, Farm Boy, Longo's).
A6: Data | B6: 19 line items x 3 companies x 6 fiscal years = 342 numbers, typed in from nine annual reports and checked against the report text.
A7: Units | B7: Millions of Canadian dollars. Costs and cash outflows are shown as positive numbers.
A8: Fiscal years | B8: Loblaw's year ends around 31 December, Metro's in late September and Empire's in early May, so 'FY2023' covers different months for each. Some years have 53 weeks (see Periods).
A9: Colour code | B9: Blue numbers are typed-in inputs; black numbers are formulas; yellow cells are drop-downs.
A11: Sheets
A12: Dashboard | B12: Key figures, a ratio table and charts; pick a company from the drop-down.
A13: Findings | B13: What the numbers show, and the limits of the data.
A14: Ratios | B14: 12 ratios for each company and year.
A15: Model | B15: The standard line items for each company, pulled from Data with SUMIFS.
A16: YoY | B16: Year-over-year changes, with explanations from the annual reports.
A17: Forecast | B17: A simple FY2026 projection under low, base and high scenarios.
A18: Pivot | B18: Pivot tables and slicers on the Data table.
A19: Checks | B19: Tie-out checks: balance sheets balance, earnings add up, gross margins match what the companies report.
A20: Data | B20: Every number with its source document and page.
A21: Map | B21: How each company's wording maps to a standard line item (used by XLOOKUP).
A22: Periods | B22: Fiscal year ends, 53-week years and company-reported gross margins.
A24: Sources
A25: Loblaw Companies Limited | B25: 2021, 2023 and 2025 Annual Reports - Financial Review | C25: https://www.loblaw.ca/en/investors-reports
A26: Metro Inc. | B26: 2021, 2023 and 2025 Annual Reports | C26: https://www.corpo.metro.ca/en/investor-relations/financial-information/annual-reports.html
A27: Empire Company Limited | B27: 2021, 2023 and 2025 Annual Reports | C27: https://www.empireco.ca/annual-documents

Sheet Dashboard
A1: Canadian grocers dashboard: Loblaw, Metro and Empire, FY2020-FY2025
A2: Source: audited annual reports. C$ millions unless stated. Change the yellow cell to switch company.
B4: Company: | C4: Loblaw
B6: Revenue FY2025 | C6: Revenue growth (per week) | D6: Gross margin | E6: EBIT margin | F6: Net margin | G6: Days inventory
B7: =SUMIFS(tblData[Amount],tblData[Company],$C$4,tblData[Fiscal year],2025,tblData[Standard line item],"Revenue")/1000 -> 63.903 | C7: =_xlfn.XLOOKUP($C$4&"|Revenue growth (per week)",Ratios!$A$5:$A$60,Ratios!$I$5:$I$60) -> 0.042816942 | D7: =_xlfn.XLOOKUP($C$4&"|Gross margin",Ratios!$A$5:$A$60,Ratios!$I$5:$I$60) -> 0.31347511 | E7: =_xlfn.XLOOKUP($C$4&"|Operating (EBIT) margin",Ratios!$A$5:$A$60,Ratios!$I$5:$I$60) -> 0.069229927 | F7: =_xlfn.XLOOKUP($C$4&"|Net margin",Ratios!$A$5:$A$60,Ratios!$I$5:$I$60) -> 0.042846189 | G7: =_xlfn.XLOOKUP($C$4&"|Days inventory",Ratios!$A$5:$A$60,Ratios!$I$5:$I$60) -> 54.891865
B8: FY2025 | C8: FY2025 | D8: FY2025 | E8: FY2025 | F8: FY2025 | G8: FY2025
B10: ="All ratios for "&$C$4 -> All ratios for Loblaw
B11: Ratio | C11: 2020 | D11: 2021 | E11: 2022 | F11: 2023 | G11: 2024 | H11: 2025
B12: Revenue growth (reported) | C12: =_xlfn.XLOOKUP($C$4&"|"&$B12,Ratios!$A$5:$A$60,Ratios!D$5:D$60) -> n/a | D12: =_xlfn.XLOOKUP($C$4&"|"&$B12,Ratios!$A$5:$A$60,Ratios!E$5:E$60) -> 0.0086504534 | E12: =_xlfn.XLOOKUP($C$4&"|"&$B12,Ratios!$A$5:$A$60,Ratios!F$5:F$60) -> 0.062704533 | F12: =_xlfn.XLOOKUP($C$4&"|"&$B12,Ratios!$A$5:$A$60,Ratios!G$5:G$60) -> 0.053536033 | G12: =_xlfn.XLOOKUP($C$4&"|"&$B12,Ratios!$A$5:$A$60,Ratios!H$5:H$60) -> 0.0099783299 | H12: =_xlfn.XLOOKUP($C$4&"|"&$B12,Ratios!$A$5:$A$60,Ratios!I$5:I$60) -> 0.062871114
B13: Revenue growth (per week) | C13: =_xlfn.XLOOKUP($C$4&"|"&$B13,Ratios!$A$5:$A$60,Ratios!D$5:D$60) -> n/a | D13: =_xlfn.XLOOKUP($C$4&"|"&$B13,Ratios!$A$5:$A$60,Ratios!E$5:E$60) -> 0.028047577 | E13: =_xlfn.XLOOKUP($C$4&"|"&$B13,Ratios!$A$5:$A$60,Ratios!F$5:F$60) -> 0.062704533 | F13: =_xlfn.XLOOKUP($C$4&"|"&$B13,Ratios!$A$5:$A$60,Ratios!G$5:G$60) -> 0.053536033 | G13: =_xlfn.XLOOKUP($C$4&"|"&$B13,Ratios!$A$5:$A$60,Ratios!H$5:H$60) -> 0.0099783299 | H13: =_xlfn.XLOOKUP($C$4&"|"&$B13,Ratios!$A$5:$A$60,Ratios!I$5:I$60) -> 0.042816942
B14: Gross margin | C14: =_xlfn.XLOOKUP($C$4&"|"&$B14,Ratios!$A$5:$A$60,Ratios!D$5:D$60) -> 0.30331601 | D14: =_xlfn.XLOOKUP($C$4&"|"&$B14,Ratios!$A$5:$A$60,Ratios!E$5:E$60) -> 0.31472635 | E14: =_xlfn.XLOOKUP($C$4&"|"&$B14,Ratios!$A$5:$A$60,Ratios!F$5:F$60) -> 0.31813677 | F14: =_xlfn.XLOOKUP($C$4&"|"&$B14,Ratios!$A$5:$A$60,Ratios!G$5:G$60) -> 0.31979371 | G14: =_xlfn.XLOOKUP($C$4&"|"&$B14,Ratios!$A$5:$A$60,Ratios!H$5:H$60) -> 0.31327445 | H14: =_xlfn.XLOOKUP($C$4&"|"&$B14,Ratios!$A$5:$A$60,Ratios!I$5:I$60) -> 0.31347511
B15: Operating (EBIT) margin | C15: =_xlfn.XLOOKUP($C$4&"|"&$B15,Ratios!$A$5:$A$60,Ratios!D$5:D$60) -> 0.044864742 | D15: =_xlfn.XLOOKUP($C$4&"|"&$B15,Ratios!$A$5:$A$60,Ratios!E$5:E$60) -> 0.055237916 | E15: =_xlfn.XLOOKUP($C$4&"|"&$B15,Ratios!$A$5:$A$60,Ratios!F$5:F$60) -> 0.059146255 | F15: =_xlfn.XLOOKUP($C$4&"|"&$B15,Ratios!$A$5:$A$60,Ratios!G$5:G$60) -> 0.062221774 | G15: =_xlfn.XLOOKUP($C$4&"|"&$B15,Ratios!$A$5:$A$60,Ratios!H$5:H$60) -> 0.057781548 | H15: =_xlfn.XLOOKUP($C$4&"|"&$B15,Ratios!$A$5:$A$60,Ratios!I$5:I$60) -> 0.069229927
B16: Net margin | C16: =_xlfn.XLOOKUP($C$4&"|"&$B16,Ratios!$A$5:$A$60,Ratios!D$5:D$60) -> 0.022612589 | D16: =_xlfn.XLOOKUP($C$4&"|"&$B16,Ratios!$A$5:$A$60,Ratios!E$5:E$60) -> 0.037163814 | E16: =_xlfn.XLOOKUP($C$4&"|"&$B16,Ratios!$A$5:$A$60,Ratios!F$5:F$60) -> 0.035289537 | F16: =_xlfn.XLOOKUP($C$4&"|"&$B16,Ratios!$A$5:$A$60,Ratios!G$5:G$60) -> 0.036738396 | G16: =_xlfn.XLOOKUP($C$4&"|"&$B16,Ratios!$A$5:$A$60,Ratios!H$5:H$60) -> 0.037839097 | H16: =_xlfn.XLOOKUP($C$4&"|"&$B16,Ratios!$A$5:$A$60,Ratios!I$5:I$60) -> 0.042846189
B17: Effective tax rate | C17: =_xlfn.XLOOKUP($C$4&"|"&$B17,Ratios!$A$5:$A$60,Ratios!D$5:D$60) -> 0.26555761 | D17: =_xlfn.XLOOKUP($C$4&"|"&$B17,Ratios!$A$5:$A$60,Ratios!E$5:E$60) -> 0.19082719 | E17: =_xlfn.XLOOKUP($C$4&"|"&$B17,Ratios!$A$5:$A$60,Ratios!F$5:F$60) -> 0.25009402 | F17: =_xlfn.XLOOKUP($C$4&"|"&$B17,Ratios!$A$5:$A$60,Ratios!G$5:G$60) -> 0.24612203 | G17: =_xlfn.XLOOKUP($C$4&"|"&$B17,Ratios!$A$5:$A$60,Ratios!H$5:H$60) -> 0.26191329 | H17: =_xlfn.XLOOKUP($C$4&"|"&$B17,Ratios!$A$5:$A$60,Ratios!I$5:I$60) -> 0.29331885
B18: Return on equity (ROE) | C18: =_xlfn.XLOOKUP($C$4&"|"&$B18,Ratios!$A$5:$A$60,Ratios!D$5:D$60) -> 0.10083728 | D18: =_xlfn.XLOOKUP($C$4&"|"&$B18,Ratios!$A$5:$A$60,Ratios!E$5:E$60) -> 0.16201503 | E18: =_xlfn.XLOOKUP($C$4&"|"&$B18,Ratios!$A$5:$A$60,Ratios!F$5:F$60) -> 0.17001505 | F18: =_xlfn.XLOOKUP($C$4&"|"&$B18,Ratios!$A$5:$A$60,Ratios!G$5:G$60) -> 0.18318214 | G18: =_xlfn.XLOOKUP($C$4&"|"&$B18,Ratios!$A$5:$A$60,Ratios!H$5:H$60) -> 0.1957443 | H18: =_xlfn.XLOOKUP($C$4&"|"&$B18,Ratios!$A$5:$A$60,Ratios!I$5:I$60) -> 0.24183896
B19: Return on assets (ROA) | C19: =_xlfn.XLOOKUP($C$4&"|"&$B19,Ratios!$A$5:$A$60,Ratios!D$5:D$60) -> 0.033228333 | D19: =_xlfn.XLOOKUP($C$4&"|"&$B19,Ratios!$A$5:$A$60,Ratios!E$5:E$60) -> 0.053968427 | E19: =_xlfn.XLOOKUP($C$4&"|"&$B19,Ratios!$A$5:$A$60,Ratios!F$5:F$60) -> 0.052271476 | F19: =_xlfn.XLOOKUP($C$4&"|"&$B19,Ratios!$A$5:$A$60,Ratios!G$5:G$60) -> 0.056107135 | G19: =_xlfn.XLOOKUP($C$4&"|"&$B19,Ratios!$A$5:$A$60,Ratios!H$5:H$60) -> 0.055650685 | H19: =_xlfn.XLOOKUP($C$4&"|"&$B19,Ratios!$A$5:$A$60,Ratios!I$5:I$60) -> 0.065853717
B20: Current ratio | C20: =_xlfn.XLOOKUP($C$4&"|"&$B20,Ratios!$A$5:$A$60,Ratios!D$5:D$60) -> 1.3171288 | D20: =_xlfn.XLOOKUP($C$4&"|"&$B20,Ratios!$A$5:$A$60,Ratios!E$5:E$60) -> 1.3741844 | E20: =_xlfn.XLOOKUP($C$4&"|"&$B20,Ratios!$A$5:$A$60,Ratios!F$5:F$60) -> 1.3246187 | F20: =_xlfn.XLOOKUP($C$4&"|"&$B20,Ratios!$A$5:$A$60,Ratios!G$5:G$60) -> 1.2517747 | G20: =_xlfn.XLOOKUP($C$4&"|"&$B20,Ratios!$A$5:$A$60,Ratios!H$5:H$60) -> 1.2362339 | H20: =_xlfn.XLOOKUP($C$4&"|"&$B20,Ratios!$A$5:$A$60,Ratios!I$5:I$60) -> 1.0762797
B21: Liabilities-to-equity | C21: =_xlfn.XLOOKUP($C$4&"|"&$B21,Ratios!$A$5:$A$60,Ratios!D$5:D$60) -> 2.2262793 | D21: =_xlfn.XLOOKUP($C$4&"|"&$B21,Ratios!$A$5:$A$60,Ratios!E$5:E$60) -> 2.1195365 | E21: =_xlfn.XLOOKUP($C$4&"|"&$B21,Ratios!$A$5:$A$60,Ratios!F$5:F$60) -> 2.3298708 | F21: =_xlfn.XLOOKUP($C$4&"|"&$B21,Ratios!$A$5:$A$60,Ratios!G$5:G$60) -> 2.3547637 | G21: =_xlfn.XLOOKUP($C$4&"|"&$B21,Ratios!$A$5:$A$60,Ratios!H$5:H$60) -> 2.6286171 | H21: =_xlfn.XLOOKUP($C$4&"|"&$B21,Ratios!$A$5:$A$60,Ratios!I$5:I$60) -> 2.7148856
B22: Days inventory | C22: =_xlfn.XLOOKUP($C$4&"|"&$B22,Ratios!$A$5:$A$60,Ratios!D$5:D$60) -> 52.480463 | D22: =_xlfn.XLOOKUP($C$4&"|"&$B22,Ratios!$A$5:$A$60,Ratios!E$5:E$60) -> 51.608958 | E22: =_xlfn.XLOOKUP($C$4&"|"&$B22,Ratios!$A$5:$A$60,Ratios!F$5:F$60) -> 55.316134 | F22: =_xlfn.XLOOKUP($C$4&"|"&$B22,Ratios!$A$5:$A$60,Ratios!G$5:G$60) -> 52.318483 | G22: =_xlfn.XLOOKUP($C$4&"|"&$B22,Ratios!$A$5:$A$60,Ratios!H$5:H$60) -> 55.806045 | H22: =_xlfn.XLOOKUP($C$4&"|"&$B22,Ratios!$A$5:$A$60,Ratios!I$5:I$60) -> 54.891865
B23: FCF margin (after leases) | C23: =_xlfn.XLOOKUP($C$4&"|"&$B23,Ratios!$A$5:$A$60,Ratios!D$5:D$60) -> 0.05708161 | D23: =_xlfn.XLOOKUP($C$4&"|"&$B23,Ratios!$A$5:$A$60,Ratios!E$5:E$60) -> 0.049369945 | E23: =_xlfn.XLOOKUP($C$4&"|"&$B23,Ratios!$A$5:$A$60,Ratios!F$5:F$60) -> 0.038758318 | F23: =_xlfn.XLOOKUP($C$4&"|"&$B23,Ratios!$A$5:$A$60,Ratios!G$5:G$60) -> 0.042181122 | G23: =_xlfn.XLOOKUP($C$4&"|"&$B23,Ratios!$A$5:$A$60,Ratios!H$5:H$60) -> 0.041847546 | H23: =_xlfn.XLOOKUP($C$4&"|"&$B23,Ratios!$A$5:$A$60,Ratios!I$5:I$60) -> 0.046116771

Sheet Findings
A1: Findings: what six years of financial statements show
A2: All numbers come from the Ratios and Model sheets.
B4: Short answer: no sign of a big margin jump. Between FY2021 and FY2023, when food inflation was highest, gross margins moved by about half a point or less and net margins stayed between 2.4% and 4.9%. Profits in dollars rose mainly because sales rose.
B6: Key findings
A7: 1 | B7: Margins barely moved during the inflation years.
B8: Gross margin FY2021 -> FY2023: Loblaw 31.5% -> 32.0% (Loblaw's own measure, which leaves out its bank: 30.7% -> 31.0%), Metro 20.0% -> 19.7%, Empire 25.5% -> 25.6%. Net margin: Loblaw 3.7% -> 3.7%, Metro 4.5% -> 4.9% (FY2023 had 53 weeks), Empire 2.7% -> 2.4%. Net earnings changed by +11% (Loblaw), +23% (Metro) and -5% (Empire).
A10: 2 | B10: Grocers keep only a few cents of each sales dollar.
B11: In FY2025 net margin was 4.3% at Loblaw, 4.6% at Metro and 2.4% at Empire: roughly 2 to 5 cents of profit per dollar of sales.
A13: 3 | B13: Three different business models.
B14: Loblaw has the highest gross margin (31.3% in FY2025), which fits its large pharmacy and beauty business (Shoppers Drug Mart), but also the highest costs. Metro has the lowest gross margin (19.9%) yet an operating margin of 6.7%, close to Loblaw's 6.9% and well above Empire's 4.1%, so it runs with the lowest costs relative to sales.
A16: 4 | B16: Empire's gross margin gains were absorbed by higher costs.
B17: Empire's gross margin rose from 24.9% (FY2020) to 26.8% (FY2025), +1.9 points, but its operating margin went from 4.2% to 4.1%. The FY2023 report links higher costs to Project Horizon investments (Voila, Farm Boy, FreshCo) and a cybersecurity incident.
A19: 5 | B19: Stock moves fastest at Empire and slowest at Loblaw.
B20: Days inventory in FY2025: Empire 29, Metro 33, Loblaw 55. Loblaw's longer figure likely reflects drugstore and general merchandise, which sell more slowly than fresh food.
A22: 6 | B22: Leases matter for cash flow.
B23: Under IFRS 16, lease payments sit in financing cash flow, so operating cash flow looks bigger. Loblaw paid $1.3bn of lease principal in FY2025, about 20% of its operating cash flow. After capex and leases, free cash flow was 4.6% of sales at Loblaw, 4.2% at Metro and 2.6% at Empire.
A25: 7 | B25: Loblaw's return on equity more than doubled, helped by buybacks.
B26: Loblaw's ROE rose from 10.1% (FY2020) to 24.2% (FY2025). Earnings to shareholders went from $1.1bn to $2.7bn, while shareholders' equity stayed near $11.0bn because the company kept buying back shares ($1.9bn in FY2025).
B28: Limits of this analysis
A29: - | B29: Fiscal years end in different months (Loblaw around December, Metro in September, Empire in May), so the same 'FY' label covers different periods.
A30: - | B30: Loblaw FY2020-FY2023 include PC Financial (its bank) in revenue and costs; FY2024-FY2025 do not, because the 2025 report restated FY2024 when PC Financial was put up for sale. This lowers Loblaw's FY2024 growth and gross margin. At the end of FY2025, PC Financial's assets and liabilities are in current items, which affects the current ratio.
A31: - | B31: Some years have 53 weeks (Loblaw FY2020 and FY2025, Metro FY2023, Empire FY2022). The per-week growth ratio corrects for this; other ratios do not need it.
A32: - | B32: The figures are for whole companies, so they include pharmacy, fuel and wholesale sales, not just grocery.
A33: - | B33: Balance sheet ratios use year-end balances rather than averages.
A34: - | B34: Margins are company-wide. They cannot show whether prices of particular foods rose faster than their costs.
B36: What I would do next
A37: - | B37: Compare the forecast for Empire FY2026 with Empire's actual FY2026 results (its 2026 annual report is out).
A38: - | B38: Add Costco and Walmart Canada if comparable Canadian figures can be found.
A39: - | B39: Use segment notes to separate food retail from pharmacy at Loblaw and Metro.

Sheet Ratios
A1: Ratios: 12 ratios x 3 companies x 6 fiscal years
A2: Every number is a formula on the Model sheet. Balance sheet ratios use year-end balances.
A4: Key | B4: Ratio | C4: Company | D4: 2020 | E4: 2021 | F4: 2022 | G4: 2023 | H4: 2024 | I4: 2025 | J4: How it is calculated
A5: =C5&"|"&B5 -> Loblaw|Revenue growth (reported) | B5: Revenue growth (reported) | C5: Loblaw | D5: n/a | E5: =Model!C6/Model!B6-1 -> 0.0086504534 | F5: =Model!D6/Model!C6-1 -> 0.062704533 | G5: =Model!E6/Model!D6-1 -> 0.053536033 | H5: =Model!F6/Model!E6-1 -> 0.0099783299 | I5: =Model!G6/Model!F6-1 -> 0.062871114 | J5: Revenue / last year's revenue - 1
A6: =C6&"|"&B6 -> Metro|Revenue growth (reported) | B6: Revenue growth (reported) | C6: Metro | D6: n/a | E6: =Model!C32/Model!B32-1 -> 0.015863314 | F6: =Model!D32/Model!C32-1 -> 0.033140075 | G6: =Model!E32/Model!D32-1 -> 0.09718406 | H6: =Model!F32/Model!E32-1 -> 0.023899134 | I6: =Model!G32/Model!F32-1 -> 0.037078403 | J6: Revenue / last year's revenue - 1
A7: =C7&"|"&B7 -> Empire|Revenue growth (reported) | B7: Revenue growth (reported) | C7: Empire | D7: n/a | E7: =Model!C58/Model!B58-1 -> 0.063189686 | F7: =Model!D58/Model!C58-1 -> 0.067004383 | G7: =Model!E58/Model!D58-1 -> 0.010466674 | H7: =Model!F58/Model!E58-1 -> 0.0083633822 | I7: =Model!G58/Model!F58-1 -> 0.017700843 | J7: Revenue / last year's revenue - 1
A9: =C9&"|"&B9 -> Loblaw|Revenue growth (per week) | B9: Revenue growth (per week) | C9: Loblaw | D9: n/a | E9: =(Model!C6/Model!C29)/(Model!B6/Model!B29)-1 -> 0.028047577 | F9: =(Model!D6/Model!D29)/(Model!C6/Model!C29)-1 -> 0.062704533 | G9: =(Model!E6/Model!E29)/(Model!D6/Model!D29)-1 -> 0.053536033 | H9: =(Model!F6/Model!F29)/(Model!E6/Model!E29)-1 -> 0.0099783299 | I9: =(Model!G6/Model!G29)/(Model!F6/Model!F29)-1 -> 0.042816942 | J9: Same, using revenue per week, so 53-week years do not inflate growth
A10: =C10&"|"&B10 -> Metro|Revenue growth (per week) | B10: Revenue growth (per week) | C10: Metro | D10: n/a | E10: =(Model!C32/Model!C55)/(Model!B32/Model!B55)-1 -> 0.015863314 | F10: =(Model!D32/Model!D55)/(Model!C32/Model!C55)-1 -> 0.033140075 | G10: =(Model!E32/Model!E55)/(Model!D32/Model!D55)-1 -> 0.076482474 | H10: =(Model!F32/Model!F55)/(Model!E32/Model!E55)-1 -> 0.043589502 | I10: =(Model!G32/Model!G55)/(Model!F32/Model!F55)-1 -> 0.037078403 | J10: Same, using revenue per week, so 53-week years do not inflate growth
A11: =C11&"|"&B11 -> Empire|Revenue growth (per week) | B11: Revenue growth (per week) | C11: Empire | D11: n/a | E11: =(Model!C58/Model!C81)/(Model!B58/Model!B81)-1 -> 0.063189686 | F11: =(Model!D58/Model!D81)/(Model!C58/Model!C81)-1 -> 0.046872225 | G11: =(Model!E58/Model!E81)/(Model!D58/Model!D81)-1 -> 0.029898725 | H11: =(Model!F58/Model!F81)/(Model!E58/Model!E81)-1 -> 0.0083633822 | I11: =(Model!G58/Model!G81)/(Model!F58/Model!F81)-1 -> 0.017700843 | J11: Same, using revenue per week, so 53-week years do not inflate growth
A13: =C13&"|"&B13 -> Loblaw|Gross margin | B13: Gross margin | C13: Loblaw | D13: =Model!B8/Model!B6 -> 0.30331601 | E13: =Model!C8/Model!C6 -> 0.31472635 | F13: =Model!D8/Model!D6 -> 0.31813677 | G13: =Model!E8/Model!E6 -> 0.31979371 | H13: =Model!F8/Model!F6 -> 0.31327445 | I13: =Model!G8/Model!G6 -> 0.31347511 | J13: (Revenue - cost of sales) / revenue
A14: =C14&"|"&B14 -> Metro|Gross margin | B14: Gross margin | C14: Metro | D14: =Model!B34/Model!B32 -> 0.19901653 | E14: =Model!C34/Model!C32 -> 0.19990155 | F14: =Model!D34/Model!D32 -> 0.20029224 | G14: =Model!E34/Model!E32 -> 0.19697364 | H14: =Model!F34/Model!F32 -> 0.19695192 | I14: =Model!G34/Model!G32 -> 0.19858952 | J14: (Revenue - cost of sales) / revenue
A15: =C15&"|"&B15 -> Empire|Gross margin | B15: Gross margin | C15: Empire | D15: =Model!B60/Model!B58 -> 0.24948285 | E15: =Model!C60/Model!C58 -> 0.2546775 | F15: =Model!D60/Model!D58 -> 0.25394862 | G15: =Model!E60/Model!E58 -> 0.25568195 | H15: =Model!F60/Model!F58 -> 0.26261673 | I15: =Model!G60/Model!G58 -> 0.26799245 | J15: (Revenue - cost of sales) / revenue
A17: =C17&"|"&B17 -> Loblaw|Operating (EBIT) margin | B17: Operating (EBIT) margin | C17: Loblaw | D17: =Model!B9/Model!B6 -> 0.044864742 | E17: =Model!C9/Model!C6 -> 0.055237916 | F17: =Model!D9/Model!D6 -> 0.059146255 | G17: =Model!E9/Model!E6 -> 0.062221774 | H17: =Model!F9/Model!F6 -> 0.057781548 | I17: =Model!G9/Model!G6 -> 0.069229927 | J17: (Earnings before income taxes + net finance costs) / revenue
A18: =C18&"|"&B18 -> Metro|Operating (EBIT) margin | B18: Operating (EBIT) margin | C18: Metro | D18: =Model!B35/Model!B32 -> 0.067848312 | E18: =Model!C35/Model!C32 -> 0.068599245 | F18: =Model!D35/Model!D32 -> 0.067298784 | G18: =Model!E35/Model!E32 -> 0.069694952 | H18: =Model!F35/Model!F32 -> 0.065777878 | I18: =Model!G35/Model!G32 -> 0.066525195 | J18: (Earnings before income taxes + net finance costs) / revenue
A19: =C19&"|"&B19 -> Empire|Operating (EBIT) margin | B19: Operating (EBIT) margin | C19: Empire | D19: =Model!B61/Model!B58 -> 0.041815542 | E19: =Model!C61/Model!C58 -> 0.045970221 | F19: =Model!D61/Model!D58 -> 0.045211919 | G19: =Model!E61/Model!E58 -> 0.040435591 | H19: =Model!F61/Model!F58 -> 0.042657729 | I19: =Model!G61/Model!G58 -> 0.041212392 | J19: (Earnings before income taxes + net finance costs) / revenue
A21: =C21&"|"&B21 -> Loblaw|Net margin | B21: Net margin | C21: Loblaw | D21: =Model!B14/Model!B6 -> 0.022612589 | E21: =Model!C14/Model!C6 -> 0.037163814 | F21: =Model!D14/Model!D6 -> 0.035289537 | G21: =Model!E14/Model!E6 -> 0.036738396 | H21: =Model!F14/Model!F6 -> 0.037839097 | I21: =Model!G14/Model!G6 -> 0.042846189 | J21: Net earnings / revenue
A22: =C22&"|"&B22 -> Metro|Net margin | B22: Net margin | C22: Metro | D22: =Model!B40/Model!B32 -> 0.04425059 | E22: =Model!C40/Model!C32 -> 0.045162173 | F22: =Model!D40/Model!D32 -> 0.044973503 | G22: =Model!E40/Model!E32 -> 0.04915897 | H22: =Model!F40/Model!F32 -> 0.043906899 | I22: =Model!G40/Model!G32 -> 0.0463268 | J22: Net earnings / revenue
A23: =C23&"|"&B23 -> Empire|Net margin | B23: Net margin | C23: Empire | D23: =Model!B66/Model!B58 -> 0.023047818 | E23: =Model!C66/Model!C58 -> 0.027033815 | F23: =Model!D66/Model!D58 -> 0.026897727 | G23: =Model!E66/Model!E58 -> 0.02387616 | H23: =Model!F66/Model!F58 -> 0.024826733 | I23: =Model!G66/Model!G58 -> 0.023851392 | J23: Net earnings / revenue
A25: =C25&"|"&B25 -> Loblaw|Effective tax rate | B25: Effective tax rate | C25: Loblaw | D25: =Model!B12/Model!B11 -> 0.26555761 | E25: =Model!C12/Model!C11 -> 0.19082719 | F25: =Model!D12/Model!D11 -> 0.25009402 | G25: =Model!E12/Model!E11 -> 0.24612203 | H25: =Model!F12/Model!F11 -> 0.26191329 | I25: =Model!G12/Model!G11 -> 0.29331885 | J25: Income taxes / earnings before taxes
A26: =C26&"|"&B26 -> Metro|Effective tax rate | B26: Effective tax rate | C26: Metro | D26: =Model!B38/Model!B37 -> 0.26551692 | E26: =Model!C38/Model!C37 -> 0.26322834 | F26: =Model!D38/Model!D37 -> 0.26360957 | G26: =Model!E38/Model!E37 -> 0.22923286 | H26: =Model!F38/Model!F37 -> 0.25469962 | I26: =Model!G38/Model!G37 -> 0.22776852 | J26: Income taxes / earnings before taxes
A27: =C27&"|"&B27 -> Empire|Effective tax rate | B27: Effective tax rate | C27: Empire | D27: =Model!B64/Model!B63 -> 0.2640807 | E27: =Model!C64/Model!C63 -> 0.25813028 | F27: =Model!D64/Model!D63 -> 0.24990754 | G27: =Model!E64/Model!E63 -> 0.24621918 | H27: =Model!F64/Model!F63 -> 0.2585034 | I27: =Model!G64/Model!G63 -> 0.25025126 | J27: Income taxes / earnings before taxes
A29: =C29&"|"&B29 -> Loblaw|Return on equity (ROE) | B29: Return on equity (ROE) | C29: Loblaw | D29: =Model!B15/Model!B22 -> 0.10083728 | E29: =Model!C15/Model!C22 -> 0.16201503 | F29: =Model!D15/Model!D22 -> 0.17001505 | G29: =Model!E15/Model!E22 -> 0.18318214 | H29: =Model!F15/Model!F22 -> 0.1957443 | I29: =Model!G15/Model!G22 -> 0.24183896 | J29: Net earnings to shareholders / shareholders' equity at year end
A30: =C30&"|"&B30 -> Metro|Return on equity (ROE) | B30: Return on equity (ROE) | C30: Metro | D30: =Model!B41/Model!B48 -> 0.12946501 | E30: =Model!C41/Model!C48 -> 0.12859576 | F30: =Model!D41/Model!D48 -> 0.12810962 | G30: =Model!E41/Model!E48 -> 0.14920896 | H30: =Model!F41/Model!F48 -> 0.13227566 | I30: =Model!G41/Model!G48 -> 0.14473366 | J30: Net earnings to shareholders / shareholders' equity at year end
A31: =C31&"|"&B31 -> Empire|Return on equity (ROE) | B31: Return on equity (ROE) | C31: Empire | D31: =Model!B67/Model!B74 -> 0.14867757 | E31: =Model!C67/Model!C74 -> 0.1604272 | F31: =Model!D67/Model!D74 -> 0.149414 | G31: =Model!E67/Model!E74 -> 0.13191293 | H31: =Model!F67/Model!F74 -> 0.1359296 | I31: =Model!G67/Model!G74 -> 0.12939002 | J31: Net earnings to shareholders / shareholders' equity at year end
A33: =C33&"|"&B33 -> Loblaw|Return on assets (ROA) | B33: Return on assets (ROA) | C33: Loblaw | D33: =Model!B14/Model!B18 -> 0.033228333 | E33: =Model!C14/Model!C18 -> 0.053968427 | F33: =Model!D14/Model!D18 -> 0.052271476 | G33: =Model!E14/Model!E18 -> 0.056107135 | H33: =Model!F14/Model!F18 -> 0.055650685 | I33: =Model!G14/Model!G18 -> 0.065853717 | J33: Net earnings / total assets at year end
A34: =C34&"|"&B34 -> Metro|Return on assets (ROA) | B34: Return on assets (ROA) | C34: Metro | D34: =Model!B40/Model!B44 -> 0.059327021 | E34: =Model!C40/Model!C44 -> 0.060748523 | F34: =Model!D40/Model!D44 -> 0.063389373 | G34: =Model!E40/Model!E44 -> 0.073478396 | H34: =Model!F40/Model!F44 -> 0.065888293 | I34: =Model!G40/Model!G44 -> 0.070119812 | J34: Net earnings / total assets at year end
A35: =C35&"|"&B35 -> Empire|Return on assets (ROA) | B35: Return on assets (ROA) | C35: Empire | D35: =Model!B66/Model!B70 -> 0.041878233 | E35: =Model!C66/Model!C70 -> 0.050362794 | F35: =Model!D66/Model!D70 -> 0.048892344 | G35: =Model!E66/Model!E70 -> 0.044146642 | H35: =Model!F66/Model!F70 -> 0.045443716 | I35: =Model!G66/Model!G70 -> 0.043833363 | J35: Net earnings / total assets at year end
A37: =C37&"|"&B37 -> Loblaw|Current ratio | B37: Current ratio | C37: Loblaw | D37: =Model!B17/Model!B19 -> 1.3171288 | E37: =Model!C17/Model!C19 -> 1.3741844 | F37: =Model!D17/Model!D19 -> 1.3246187 | G37: =Model!E17/Model!E19 -> 1.2517747 | H37: =Model!F17/Model!F19 -> 1.2362339 | I37: =Model!G17/Model!G19 -> 1.0762797 | J37: Current assets / current liabilities
A38: =C38&"|"&B38 -> Metro|Current ratio | B38: Current ratio | C38: Metro | D38: =Model!B43/Model!B45 -> 1.3442826 | E38: =Model!C43/Model!C45 -> 1.1221909 | F38: =Model!D43/Model!D45 -> 1.1182074 | G38: =Model!E43/Model!E45 -> 1.2258262 | H38: =Model!F43/Model!F45 -> 1.0824291 | I38: =Model!G43/Model!G45 -> 1.2956471 | J38: Current assets / current liabilities
A39: =C39&"|"&B39 -> Empire|Current ratio | B39: Current ratio | C39: Empire | D39: =Model!B69/Model!B71 -> 0.80184729 | E39: =Model!C69/Model!C71 -> 0.91551517 | F39: =Model!D69/Model!D71 -> 0.75776588 | G39: =Model!E69/Model!E71 -> 0.76604018 | H39: =Model!F69/Model!F71 -> 0.79773837 | I39: =Model!G69/Model!G71 -> 0.76513672 | J39: Current assets / current liabilities
A41: =C41&"|"&B41 -> Loblaw|Liabilities-to-equity | B41: Liabilities-to-equity | C41: Loblaw | D41: =Model!B20/Model!B21 -> 2.2262793 | E41: =Model!C20/Model!C21 -> 2.1195365 | F41: =Model!D20/Model!D21 -> 2.3298708 | G41: =Model!E20/Model!E21 -> 2.3547637 | H41: =Model!F20/Model!F21 -> 2.6286171 | I41: =Model!G20/Model!G21 -> 2.7148856 | J41: Total liabilities / total equity
A42: =C42&"|"&B42 -> Metro|Liabilities-to-equity | B42: Liabilities-to-equity | C42: Metro | D42: =Model!B46/Model!B47 -> 1.1808331 | E42: =Model!C46/Model!C47 -> 1.1195266 | F42: =Model!D46/Model!D47 -> 1.0248549 | G42: =Model!E46/Model!E47 -> 1.0341388 | H42: =Model!F46/Model!F47 -> 1.0089218 | I42: =Model!G46/Model!G47 -> 1.0637606 | J42: Total liabilities / total equity
A43: =C43&"|"&B43 -> Empire|Liabilities-to-equity | B43: Liabilities-to-equity | C43: Empire | D43: =Model!B72/Model!B73 -> 2.6455567 | E43: =Model!C72/Model!C73 -> 2.3734771 | F43: =Model!D72/Model!D73 -> 2.2321627 | G43: =Model!E72/Model!E73 -> 2.088744 | H43: =Model!F72/Model!F73 -> 2.0700311 | I43: =Model!G72/Model!G73 -> 2.0698052 | J43: Total liabilities / total equity
A45: =C45&"|"&B45 -> Loblaw|Days inventory | B45: Days inventory | C45: Loblaw | D45: =Model!B16/Model!B7*Model!B29*7 -> 52.480463 | E45: =Model!C16/Model!C7*Model!C29*7 -> 51.608958 | F45: =Model!D16/Model!D7*Model!D29*7 -> 55.316134 | G45: =Model!E16/Model!E7*Model!E29*7 -> 52.318483 | H45: =Model!F16/Model!F7*Model!F29*7 -> 55.806045 | I45: =Model!G16/Model!G7*Model!G29*7 -> 54.891865 | J45: Inventory / cost of sales x days in the fiscal year
A46: =C46&"|"&B46 -> Metro|Days inventory | B46: Days inventory | C46: Metro | D46: =Model!B42/Model!B33*Model!B55*7 -> 32.022365 | E46: =Model!C42/Model!C33*Model!C55*7 -> 29.088746 | F46: =Model!D42/Model!D33*Model!D55*7 -> 32.075548 | G46: =Model!E42/Model!E33*Model!E55*7 -> 32.346356 | H46: =Model!F42/Model!F33*Model!F55*7 -> 32.21842 | I46: =Model!G42/Model!G33*Model!G55*7 -> 33.111361 | J46: Inventory / cost of sales x days in the fiscal year
A47: =C47&"|"&B47 -> Empire|Days inventory | B47: Days inventory | C47: Empire | D47: =Model!B68/Model!B59*Model!B81*7 -> 27.168345 | E47: =Model!C68/Model!C59*Model!C81*7 -> 25.916579 | F47: =Model!D68/Model!D59*Model!D81*7 -> 26.238918 | G47: =Model!E68/Model!E59*Model!E81*7 -> 27.972229 | H47: =Model!F68/Model!F59*Model!F81*7 -> 28.462095 | I47: =Model!G68/Model!G59*Model!G81*7 -> 29.142258 | J47: Inventory / cost of sales x days in the fiscal year
A49: =C49&"|"&B49 -> Loblaw|FCF margin (after leases) | B49: FCF margin (after leases) | C49: Loblaw | D49: =Model!B28/Model!B6 -> 0.05708161 | E49: =Model!C28/Model!C6 -> 0.049369945 | F49: =Model!D28/Model!D6 -> 0.038758318 | G49: =Model!E28/Model!E6 -> 0.042181122 | H49: =Model!F28/Model!F6 -> 0.041847546 | I49: =Model!G28/Model!G6 -> 0.046116771 | J49: (Operating cash flow - capex - lease principal) / revenue
A50: =C50&"|"&B50 -> Metro|FCF margin (after leases) | B50: FCF margin (after leases) | C50: Metro | D50: =Model!B54/Model!B32 -> 0.039477705 | E50: =Model!C54/Model!C32 -> 0.039550402 | F50: =Model!D54/Model!D32 -> 0.030303512 | G50: =Model!E54/Model!E32 -> 0.029650753 | H50: =Model!F54/Model!F32 -> 0.039090665 | I50: =Model!G54/Model!G32 -> 0.042378003 | J50: (Operating cash flow - capex - lease principal) / revenue
A51: =C51&"|"&B51 -> Empire|FCF margin (after leases) | B51: FCF margin (after leases) | C51: Empire | D51: =Model!B80/Model!B58 -> 0.040600718 | E51: =Model!C80/Model!C58 -> 0.027606895 | F51: =Model!D80/Model!D58 -> 0.027981858 | G51: =Model!E80/Model!E58 -> 0.011155551 | H51: =Model!F80/Model!F58 -> 0.02430612 | I51: =Model!G80/Model!G58 -> 0.025641845 | J51: (Operating cash flow - capex - lease principal) / revenue

Sheet Model
A1: Model: the 19 standard line items for each company, plus a few derived lines
A2: Each white cell is a SUMIFS on the Data table; italic rows are calculated from the rows above.
A4: C$ millions | B4: 2020 | C4: 2021 | D4: 2022 | E4: 2023 | F4: 2024 | G4: 2025
A5: Loblaw
A6: Revenue | B6: =SUMIFS(tblData[Amount],tblData[Company],$A$5,tblData[Fiscal year],B$4,tblData[Standard line item],$A6) -> 52714 | C6: =SUMIFS(tblData[Amount],tblData[Company],$A$5,tblData[Fiscal year],C$4,tblData[Standard line item],$A6) -> 53170 | D6: =SUMIFS(tblData[Amount],tblData[Company],$A$5,tblData[Fiscal year],D$4,tblData[Standard line item],$A6) -> 56504 | E6: =SUMIFS(tblData[Amount],tblData[Company],$A$5,tblData[Fiscal year],E$4,tblData[Standard line item],$A6) -> 59529 | F6: =SUMIFS(tblData[Amount],tblData[Company],$A$5,tblData[Fiscal year],F$4,tblData[Standard line item],$A6) -> 60123 | G6: =SUMIFS(tblData[Amount],tblData[Company],$A$5,tblData[Fiscal year],G$4,tblData[Standard line item],$A6) -> 63903
A7: Cost of sales | B7: =SUMIFS(tblData[Amount],tblData[Company],$A$5,tblData[Fiscal year],B$4,tblData[Standard line item],$A7) -> 36725 | C7: =SUMIFS(tblData[Amount],tblData[Company],$A$5,tblData[Fiscal year],C$4,tblData[Standard line item],$A7) -> 36436 | D7: =SUMIFS(tblData[Amount],tblData[Company],$A$5,tblData[Fiscal year],D$4,tblData[Standard line item],$A7) -> 38528 | E7: =SUMIFS(tblData[Amount],tblData[Company],$A$5,tblData[Fiscal year],E$4,tblData[Standard line item],$A7) -> 40492 | F7: =SUMIFS(tblData[Amount],tblData[Company],$A$5,tblData[Fiscal year],F$4,tblData[Standard line item],$A7) -> 41288 | G7: =SUMIFS(tblData[Amount],tblData[Company],$A$5,tblData[Fiscal year],G$4,tblData[Standard line item],$A7) -> 43871
A8: Gross profit | B8: =B6-B7 -> 15989 | C8: =C6-C7 -> 16734 | D8: =D6-D7 -> 17976 | E8: =E6-E7 -> 19037 | F8: =F6-F7 -> 18835 | G8: =G6-G7 -> 20032
A9: Operating income (EBIT) | B9: =B11+B10 -> 2365 | C9: =C11+C10 -> 2937 | D9: =D11+D10 -> 3342 | E9: =E11+E10 -> 3704 | F9: =F11+F10 -> 3474 | G9: =G11+G10 -> 4424
A10: Net finance costs | B10: =SUMIFS(tblData[Amount],tblData[Company],$A$5,tblData[Fiscal year],B$4,tblData[Standard line item],$A10) -> 742 | C10: =SUMIFS(tblData[Amount],tblData[Company],$A$5,tblData[Fiscal year],C$4,tblData[Standard line item],$A10) -> 495 | D10: =SUMIFS(tblData[Amount],tblData[Company],$A$5,tblData[Fiscal year],D$4,tblData[Standard line item],$A10) -> 683 | E10: =SUMIFS(tblData[Amount],tblData[Company],$A$5,tblData[Fiscal year],E$4,tblData[Standard line item],$A10) -> 803 | F10: =SUMIFS(tblData[Amount],tblData[Company],$A$5,tblData[Fiscal year],F$4,tblData[Standard line item],$A10) -> 683 | G10: =SUMIFS(tblData[Amount],tblData[Company],$A$5,tblData[Fiscal year],G$4,tblData[Standard line item],$A10) -> 742
A11: Earnings before income taxes | B11: =SUMIFS(tblData[Amount],tblData[Company],$A$5,tblData[Fiscal year],B$4,tblData[Standard line item],$A11) -> 1623 | C11: =SUMIFS(tblData[Amount],tblData[Company],$A$5,tblData[Fiscal year],C$4,tblData[Standard line item],$A11) -> 2442 | D11: =SUMIFS(tblData[Amount],tblData[Company],$A$5,tblData[Fiscal year],D$4,tblData[Standard line item],$A11) -> 2659 | E11: =SUMIFS(tblData[Amount],tblData[Company],$A$5,tblData[Fiscal year],E$4,tblData[Standard line item],$A11) -> 2901 | F11: =SUMIFS(tblData[Amount],tblData[Company],$A$5,tblData[Fiscal year],F$4,tblData[Standard line item],$A11) -> 2791 | G11: =SUMIFS(tblData[Amount],tblData[Company],$A$5,tblData[Fiscal year],G$4,tblData[Standard line item],$A11) -> 3682
A12: Income taxes | B12: =SUMIFS(tblData[Amount],tblData[Company],$A$5,tblData[Fiscal year],B$4,tblData[Standard line item],$A12) -> 431 | C12: =SUMIFS(tblData[Amount],tblData[Company],$A$5,tblData[Fiscal year],C$4,tblData[Standard line item],$A12) -> 466 | D12: =SUMIFS(tblData[Amount],tblData[Company],$A$5,tblData[Fiscal year],D$4,tblData[Standard line item],$A12) -> 665 | E12: =SUMIFS(tblData[Amount],tblData[Company],$A$5,tblData[Fiscal year],E$4,tblData[Standard line item],$A12) -> 714 | F12: =SUMIFS(tblData[Amount],tblData[Company],$A$5,tblData[Fiscal year],F$4,tblData[Standard line item],$A12) -> 731 | G12: =SUMIFS(tblData[Amount],tblData[Company],$A$5,tblData[Fiscal year],G$4,tblData[Standard line item],$A12) -> 1080
A13: Net earnings from discontinued operations | B13: =SUMIFS(tblData[Amount],tblData[Company],$A$5,tblData[Fiscal year],B$4,tblData[Standard line item],$A13) -> 0 | C13: =SUMIFS(tblData[Amount],tblData[Company],$A$5,tblData[Fiscal year],C$4,tblData[Standard line item],$A13) -> 0 | D13: =SUMIFS(tblData[Amount],tblData[Company],$A$5,tblData[Fiscal year],D$4,tblData[Standard line item],$A13) -> 0 | E13: =SUMIFS(tblData[Amount],tblData[Company],$A$5,tblData[Fiscal year],E$4,tblData[Standard line item],$A13) -> 0 | F13: =SUMIFS(tblData[Amount],tblData[Company],$A$5,tblData[Fiscal year],F$4,tblData[Standard line item],$A13) -> 215 | G13: =SUMIFS(tblData[Amount],tblData[Company],$A$5,tblData[Fiscal year],G$4,tblData[Standard line item],$A13) -> 136
A14: Net earnings | B14: =SUMIFS(tblData[Amount],tblData[Company],$A$5,tblData[Fiscal year],B$4,tblData[Standard line item],$A14) -> 1192 | C14: =SUMIFS(tblData[Amount],tblData[Company],$A$5,tblData[Fiscal year],C$4,tblData[Standard line item],$A14) -> 1976 | D14: =SUMIFS(tblData[Amount],tblData[Company],$A$5,tblData[Fiscal year],D$4,tblData[Standard line item],$A14) -> 1994 | E14: =SUMIFS(tblData[Amount],tblData[Company],$A$5,tblData[Fiscal year],E$4,tblData[Standard line item],$A14) -> 2187 | F14: =SUMIFS(tblData[Amount],tblData[Company],$A$5,tblData[Fiscal year],F$4,tblData[Standard line item],$A14) -> 2275 | G14: =SUMIFS(tblData[Amount],tblData[Company],$A$5,tblData[Fiscal year],G$4,tblData[Standard line item],$A14) -> 2738
A15: Net earnings attributable to shareholders | B15: =SUMIFS(tblData[Amount],tblData[Company],$A$5,tblData[Fiscal year],B$4,tblData[Standard line item],$A15) -> 1108 | C15: =SUMIFS(tblData[Amount],tblData[Company],$A$5,tblData[Fiscal year],C$4,tblData[Standard line item],$A15) -> 1875 | D15: =SUMIFS(tblData[Amount],tblData[Company],$A$5,tblData[Fiscal year],D$4,tblData[Standard line item],$A15) -> 1921 | E15: =SUMIFS(tblData[Amount],tblData[Company],$A$5,tblData[Fiscal year],E$4,tblData[Standard line item],$A15) -> 2100 | F15: =SUMIFS(tblData[Amount],tblData[Company],$A$5,tblData[Fiscal year],F$4,tblData[Standard line item],$A15) -> 2171 | G15: =SUMIFS(tblData[Amount],tblData[Company],$A$5,tblData[Fiscal year],G$4,tblData[Standard line item],$A15) -> 2667
A16: Inventories | B16: =SUMIFS(tblData[Amount],tblData[Company],$A$5,tblData[Fiscal year],B$4,tblData[Standard line item],$A16) -> 5195 | C16: =SUMIFS(tblData[Amount],tblData[Company],$A$5,tblData[Fiscal year],C$4,tblData[Standard line item],$A16) -> 5166 | D16: =SUMIFS(tblData[Amount],tblData[Company],$A$5,tblData[Fiscal year],D$4,tblData[Standard line item],$A16) -> 5855 | E16: =SUMIFS(tblData[Amount],tblData[Company],$A$5,tblData[Fiscal year],E$4,tblData[Standard line item],$A16) -> 5820 | F16: =SUMIFS(tblData[Amount],tblData[Company],$A$5,tblData[Fiscal year],F$4,tblData[Standard line item],$A16) -> 6330 | G16: =SUMIFS(tblData[Amount],tblData[Company],$A$5,tblData[Fiscal year],G$4,tblData[Standard line item],$A16) -> 6491
A17: Total current assets | B17: =SUMIFS(tblData[Amount],tblData[Company],$A$5,tblData[Fiscal year],B$4,tblData[Standard line item],$A17) -> 11542 | C17: =SUMIFS(tblData[Amount],tblData[Company],$A$5,tblData[Fiscal year],C$4,tblData[Standard line item],$A17) -> 12637 | D17: =SUMIFS(tblData[Amount],tblData[Company],$A$5,tblData[Fiscal year],D$4,tblData[Standard line item],$A17) -> 13376 | E17: =SUMIFS(tblData[Amount],tblData[Company],$A$5,tblData[Fiscal year],E$4,tblData[Standard line item],$A17) -> 13578 | F17: =SUMIFS(tblData[Amount],tblData[Company],$A$5,tblData[Fiscal year],F$4,tblData[Standard line item],$A17) -> 14548 | G17: =SUMIFS(tblData[Amount],tblData[Company],$A$5,tblData[Fiscal year],G$4,tblData[Standard line item],$A17) -> 14928
A18: Total assets | B18: =SUMIFS(tblData[Amount],tblData[Company],$A$5,tblData[Fiscal year],B$4,tblData[Standard line item],$A18) -> 35873 | C18: =SUMIFS(tblData[Amount],tblData[Company],$A$5,tblData[Fiscal year],C$4,tblData[Standard line item],$A18) -> 36614 | D18: =SUMIFS(tblData[Amount],tblData[Company],$A$5,tblData[Fiscal year],D$4,tblData[Standard line item],$A18) -> 38147 | E18: =SUMIFS(tblData[Amount],tblData[Company],$A$5,tblData[Fiscal year],E$4,tblData[Standard line item],$A18) -> 38979 | F18: =SUMIFS(tblData[Amount],tblData[Company],$A$5,tblData[Fiscal year],F$4,tblData[Standard line item],$A18) -> 40880 | G18: =SUMIFS(tblData[Amount],tblData[Company],$A$5,tblData[Fiscal year],G$4,tblData[Standard line item],$A18) -> 41577
A19: Total current liabilities | B19: =SUMIFS(tblData[Amount],tblData[Company],$A$5,tblData[Fiscal year],B$4,tblData[Standard line item],$A19) -> 8763 | C19: =SUMIFS(tblData[Amount],tblData[Company],$A$5,tblData[Fiscal year],C$4,tblData[Standard line item],$A19) -> 9196 | D19: =SUMIFS(tblData[Amount],tblData[Company],$A$5,tblData[Fiscal year],D$4,tblData[Standard line item],$A19) -> 10098 | E19: =SUMIFS(tblData[Amount],tblData[Company],$A$5,tblData[Fiscal year],E$4,tblData[Standard line item],$A19) -> 10847 | F19: =SUMIFS(tblData[Amount],tblData[Company],$A$5,tblData[Fiscal year],F$4,tblData[Standard line item],$A19) -> 11768 | G19: =SUMIFS(tblData[Amount],tblData[Company],$A$5,tblData[Fiscal year],G$4,tblData[Standard line item],$A19) -> 13870
A20: Total liabilities | B20: =SUMIFS(tblData[Amount],tblData[Company],$A$5,tblData[Fiscal year],B$4,tblData[Standard line item],$A20) -> 24754 | C20: =SUMIFS(tblData[Amount],tblData[Company],$A$5,tblData[Fiscal year],C$4,tblData[Standard line item],$A20) -> 24877 | D20: =SUMIFS(tblData[Amount],tblData[Company],$A$5,tblData[Fiscal year],D$4,tblData[Standard line item],$A20) -> 26691 | E20: =SUMIFS(tblData[Amount],tblData[Company],$A$5,tblData[Fiscal year],E$4,tblData[Standard line item],$A20) -> 27360 | F20: =SUMIFS(tblData[Amount],tblData[Company],$A$5,tblData[Fiscal year],F$4,tblData[Standard line item],$A20) -> 29614 | G20: =SUMIFS(tblData[Amount],tblData[Company],$A$5,tblData[Fiscal year],G$4,tblData[Standard line item],$A20) -> 30385
A21: Total equity | B21: =SUMIFS(tblData[Amount],tblData[Company],$A$5,tblData[Fiscal year],B$4,tblData[Standard line item],$A21) -> 11119 | C21: =SUMIFS(tblData[Amount],tblData[Company],$A$5,tblData[Fiscal year],C$4,tblData[Standard line item],$A21) -> 11737 | D21: =SUMIFS(tblData[Amount],tblData[Company],$A$5,tblData[Fiscal year],D$4,tblData[Standard line item],$A21) -> 11456 | E21: =SUMIFS(tblData[Amount],tblData[Company],$A$5,tblData[Fiscal year],E$4,tblData[Standard line item],$A21) -> 11619 | F21: =SUMIFS(tblData[Amount],tblData[Company],$A$5,tblData[Fiscal year],F$4,tblData[Standard line item],$A21) -> 11266 | G21: =SUMIFS(tblData[Amount],tblData[Company],$A$5,tblData[Fiscal year],G$4,tblData[Standard line item],$A21) -> 11192
... A25: Purchases of intangible assets | B25: =SUMIFS(tblData[Amount],tblData[Company],$A$5,tblData[Fiscal year],B$4,tblData[Standard line item],$A25) -> 338 | C25: =SUMIFS(tblData[Amount],tblData[Company],$A$5,tblData[Fiscal year],C$4,tblData[Standard line item],$A25) -> 379 | D25: =SUMIFS(tblData[Amount],tblData[Company],$A$5,tblData[Fiscal year],D$4,tblData[Standard line item],$A25) -> 419 | E25: =SUMIFS(tblData[Amount],tblData[Company],$A$5,tblData[Fiscal year],E$4,tblData[Standard line item],$A25) -> 407 | F25: =SUMIFS(tblData[Amount],tblData[Company],$A$5,tblData[Fiscal year],F$4,tblData[Standard line item],$A25) -> 377 | G25: =SUMIFS(tblData[Amount],tblData[Company],$A$5,tblData[Fiscal year],G$4,tblData[Standard line item],$A25) -> 350
A26: Capital expenditures | B26: =B24+B25 -> 1158 | C26: =C24+C25 -> 1182 | D26: =D24+D25 -> 1571 | E26: =E24+E25 -> 2072 | F26: =F24+F25 -> 2200 | G26: =G24+G25 -> 2062
A27: Lease principal payments | B27: =SUMIFS(tblData[Amount],tblData[Company],$A$5,tblData[Fiscal year],B$4,tblData[Standard line item],$A27) -> 1024 | C27: =SUMIFS(tblData[Amount],tblData[Company],$A$5,tblData[Fiscal year],C$4,tblData[Standard line item],$A27) -> 1020 | D27: =SUMIFS(tblData[Amount],tblData[Company],$A$5,tblData[Fiscal year],D$4,tblData[Standard line item],$A27) -> 994 | E27: =SUMIFS(tblData[Amount],tblData[Company],$A$5,tblData[Fiscal year],E$4,tblData[Standard line item],$A27) -> 1071 | F27: =SUMIFS(tblData[Amount],tblData[Company],$A$5,tblData[Fiscal year],F$4,tblData[Standard line item],$A27) -> 1086 | G27: =SUMIFS(tblData[Amount],tblData[Company],$A$5,tblData[Fiscal year],G$4,tblData[Standard line item],$A27) -> 1255
A28: Free cash flow after leases | B28: =B23-B26-B27 -> 3009 | C28: =C23-C26-C27 -> 2625 | D28: =D23-D26-D27 -> 2190 | E28: =E23-E26-E27 -> 2511 | F28: =F23-F26-F27 -> 2516 | G28: =G23-G26-G27 -> 2947
A29: Weeks in fiscal year | B29: =_xlfn.XLOOKUP($A$5&"|"&B$4,tblPeriods[Key],tblPeriods[Weeks]) -> 53 | C29: =_xlfn.XLOOKUP($A$5&"|"&C$4,tblPeriods[Key],tblPeriods[Weeks]) -> 52 | D29: =_xlfn.XLOOKUP($A$5&"|"&D$4,tblPeriods[Key],tblPeriods[Weeks]) -> 52 | E29: =_xlfn.XLOOKUP($A$5&"|"&E$4,tblPeriods[Key],tblPeriods[Weeks]) -> 52 | F29: =_xlfn.XLOOKUP($A$5&"|"&F$4,tblPeriods[Key],tblPeriods[Weeks]) -> 52 | G29: =_xlfn.XLOOKUP($A$5&"|"&G$4,tblPeriods[Key],tblPeriods[Weeks]) -> 53
A31: Metro
A32: Revenue | B32: =SUMIFS(tblData[Amount],tblData[Company],$A$31,tblData[Fiscal year],B$4,tblData[Standard line item],$A32) -> 17997.5 | C32: =SUMIFS(tblData[Amount],tblData[Company],$A$31,tblData[Fiscal year],C$4,tblData[Standard line item],$A32) -> 18283 | D32: =SUMIFS(tblData[Amount],tblData[Company],$A$31,tblData[Fiscal year],D$4,tblData[Standard line item],$A32) -> 18888.9 | E32: =SUMIFS(tblData[Amount],tblData[Company],$A$31,tblData[Fiscal year],E$4,tblData[Standard line item],$A32) -> 20724.6 | F32: =SUMIFS(tblData[Amount],tblData[Company],$A$31,tblData[Fiscal year],F$4,tblData[Standard line item],$A32) -> 21219.9 | G32: =SUMIFS(tblData[Amount],tblData[Company],$A$31,tblData[Fiscal year],G$4,tblData[Standard line item],$A32) -> 22006.7
A33: Cost of sales | B33: =SUMIFS(tblData[Amount],tblData[Company],$A$31,tblData[Fiscal year],B$4,tblData[Standard line item],$A33) -> 14415.7 | C33: =SUMIFS(tblData[Amount],tblData[Company],$A$31,tblData[Fiscal year],C$4,tblData[Standard line item],$A33) -> 14628.2 | D33: =SUMIFS(tblData[Amount],tblData[Company],$A$31,tblData[Fiscal year],D$4,tblData[Standard line item],$A33) -> 15105.6 | E33: =SUMIFS(tblData[Amount],tblData[Company],$A$31,tblData[Fiscal year],E$4,tblData[Standard line item],$A33) -> 16642.4 | F33: =SUMIFS(tblData[Amount],tblData[Company],$A$31,tblData[Fiscal year],F$4,tblData[Standard line item],$A33) -> 17040.6 | G33: =SUMIFS(tblData[Amount],tblData[Company],$A$31,tblData[Fiscal year],G$4,tblData[Standard line item],$A33) -> 17636.4
A34: Gross profit | B34: =B32-B33 -> 3581.8 | C34: =C32-C33 -> 3654.8 | D34: =D32-D33 -> 3783.3 | E34: =E32-E33 -> 4082.2 | F34: =F32-F33 -> 4179.3 | G34: =G32-G33 -> 4370.3
A35: Operating income (EBIT) | B35: =B37+B36 -> 1221.1 | C35: =C37+C36 -> 1254.2 | D35: =D37+D36 -> 1271.2 | E35: =E37+E36 -> 1444.4 | F35: =F37+F36 -> 1395.8 | G35: =G37+G36 -> 1464
A36: Net finance costs | B36: =SUMIFS(tblData[Amount],tblData[Company],$A$31,tblData[Fiscal year],B$4,tblData[Standard line item],$A36) -> 136.8 | C36: =SUMIFS(tblData[Amount],tblData[Company],$A$31,tblData[Fiscal year],C$4,tblData[Standard line item],$A36) -> 133.5 | D36: =SUMIFS(tblData[Amount],tblData[Company],$A$31,tblData[Fiscal year],D$4,tblData[Standard line item],$A36) -> 117.6 | E36: =SUMIFS(tblData[Amount],tblData[Company],$A$31,tblData[Fiscal year],E$4,tblData[Standard line item],$A36) -> 122.6 | F36: =SUMIFS(tblData[Amount],tblData[Company],$A$31,tblData[Fiscal year],F$4,tblData[Standard line item],$A36) -> 145.7 | G36: =SUMIFS(tblData[Amount],tblData[Company],$A$31,tblData[Fiscal year],G$4,tblData[Standard line item],$A36) -> 143.8
A37: Earnings before income taxes | B37: =SUMIFS(tblData[Amount],tblData[Company],$A$31,tblData[Fiscal year],B$4,tblData[Standard line item],$A37) -> 1084.3 | C37: =SUMIFS(tblData[Amount],tblData[Company],$A$31,tblData[Fiscal year],C$4,tblData[Standard line item],$A37) -> 1120.7 | D37: =SUMIFS(tblData[Amount],tblData[Company],$A$31,tblData[Fiscal year],D$4,tblData[Standard line item],$A37) -> 1153.6 | E37: =SUMIFS(tblData[Amount],tblData[Company],$A$31,tblData[Fiscal year],E$4,tblData[Standard line item],$A37) -> 1321.8 | F37: =SUMIFS(tblData[Amount],tblData[Company],$A$31,tblData[Fiscal year],F$4,tblData[Standard line item],$A37) -> 1250.1 | G37: =SUMIFS(tblData[Amount],tblData[Company],$A$31,tblData[Fiscal year],G$4,tblData[Standard line item],$A37) -> 1320.2
A38: Income taxes | B38: =SUMIFS(tblData[Amount],tblData[Company],$A$31,tblData[Fiscal year],B$4,tblData[Standard line item],$A38) -> 287.9 | C38: =SUMIFS(tblData[Amount],tblData[Company],$A$31,tblData[Fiscal year],C$4,tblData[Standard line item],$A38) -> 295 | D38: =SUMIFS(tblData[Amount],tblData[Company],$A$31,tblData[Fiscal year],D$4,tblData[Standard line item],$A38) -> 304.1 | E38: =SUMIFS(tblData[Amount],tblData[Company],$A$31,tblData[Fiscal year],E$4,tblData[Standard line item],$A38) -> 303 | F38: =SUMIFS(tblData[Amount],tblData[Company],$A$31,tblData[Fiscal year],F$4,tblData[Standard line item],$A38) -> 318.4 | G38: =SUMIFS(tblData[Amount],tblData[Company],$A$31,tblData[Fiscal year],G$4,tblData[Standard line item],$A38) -> 300.7
A39: Net earnings from discontinued operations | B39: =SUMIFS(tblData[Amount],tblData[Company],$A$31,tblData[Fiscal year],B$4,tblData[Standard line item],$A39) -> 0 | C39: =SUMIFS(tblData[Amount],tblData[Company],$A$31,tblData[Fiscal year],C$4,tblData[Standard line item],$A39) -> 0 | D39: =SUMIFS(tblData[Amount],tblData[Company],$A$31,tblData[Fiscal year],D$4,tblData[Standard line item],$A39) -> 0 | E39: =SUMIFS(tblData[Amount],tblData[Company],$A$31,tblData[Fiscal year],E$4,tblData[Standard line item],$A39) -> 0 | F39: =SUMIFS(tblData[Amount],tblData[Company],$A$31,tblData[Fiscal year],F$4,tblData[Standard line item],$A39) -> 0 | G39: =SUMIFS(tblData[Amount],tblData[Company],$A$31,tblData[Fiscal year],G$4,tblData[Standard line item],$A39) -> 0
A40: Net earnings | B40: =SUMIFS(tblData[Amount],tblData[Company],$A$31,tblData[Fiscal year],B$4,tblData[Standard line item],$A40) -> 796.4 | C40: =SUMIFS(tblData[Amount],tblData[Company],$A$31,tblData[Fiscal year],C$4,tblData[Standard line item],$A40) -> 825.7 | D40: =SUMIFS(tblData[Amount],tblData[Company],$A$31,tblData[Fiscal year],D$4,tblData[Standard line item],$A40) -> 849.5 | E40: =SUMIFS(tblData[Amount],tblData[Company],$A$31,tblData[Fiscal year],E$4,tblData[Standard line item],$A40) -> 1018.8 | F40: =SUMIFS(tblData[Amount],tblData[Company],$A$31,tblData[Fiscal year],F$4,tblData[Standard line item],$A40) -> 931.7 | G40: =SUMIFS(tblData[Amount],tblData[Company],$A$31,tblData[Fiscal year],G$4,tblData[Standard line item],$A40) -> 1019.5
A41: Net earnings attributable to shareholders | B41: =SUMIFS(tblData[Amount],tblData[Company],$A$31,tblData[Fiscal year],B$4,tblData[Standard line item],$A41) -> 795.2 | C41: =SUMIFS(tblData[Amount],tblData[Company],$A$31,tblData[Fiscal year],C$4,tblData[Standard line item],$A41) -> 823 | D41: =SUMIFS(tblData[Amount],tblData[Company],$A$31,tblData[Fiscal year],D$4,tblData[Standard line item],$A41) -> 846.1 | E41: =SUMIFS(tblData[Amount],tblData[Company],$A$31,tblData[Fiscal year],E$4,tblData[Standard line item],$A41) -> 1014.8 | F41: =SUMIFS(tblData[Amount],tblData[Company],$A$31,tblData[Fiscal year],F$4,tblData[Standard line item],$A41) -> 928.8 | G41: =SUMIFS(tblData[Amount],tblData[Company],$A$31,tblData[Fiscal year],G$4,tblData[Standard line item],$A41) -> 1017
A42: Inventories | B42: =SUMIFS(tblData[Amount],tblData[Company],$A$31,tblData[Fiscal year],B$4,tblData[Standard line item],$A42) -> 1268.2 | C42: =SUMIFS(tblData[Amount],tblData[Company],$A$31,tblData[Fiscal year],C$4,tblData[Standard line item],$A42) -> 1169 | D42: =SUMIFS(tblData[Amount],tblData[Company],$A$31,tblData[Fiscal year],D$4,tblData[Standard line item],$A42) -> 1331.1 | E42: =SUMIFS(tblData[Amount],tblData[Company],$A$31,tblData[Fiscal year],E$4,tblData[Standard line item],$A42) -> 1451 | F42: =SUMIFS(tblData[Amount],tblData[Company],$A$31,tblData[Fiscal year],F$4,tblData[Standard line item],$A42) -> 1508.3 | G42: =SUMIFS(tblData[Amount],tblData[Company],$A$31,tblData[Fiscal year],G$4,tblData[Standard line item],$A42) -> 1604.3
A43: Total current assets | B43: =SUMIFS(tblData[Amount],tblData[Company],$A$31,tblData[Fiscal year],B$4,tblData[Standard line item],$A43) -> 2500.5 | C43: =SUMIFS(tblData[Amount],tblData[Company],$A$31,tblData[Fiscal year],C$4,tblData[Standard line item],$A43) -> 2466.8 | D43: =SUMIFS(tblData[Amount],tblData[Company],$A$31,tblData[Fiscal year],D$4,tblData[Standard line item],$A43) -> 2183.3 | E43: =SUMIFS(tblData[Amount],tblData[Company],$A$31,tblData[Fiscal year],E$4,tblData[Standard line item],$A43) -> 2403.6 | F43: =SUMIFS(tblData[Amount],tblData[Company],$A$31,tblData[Fiscal year],F$4,tblData[Standard line item],$A43) -> 2474 | G43: =SUMIFS(tblData[Amount],tblData[Company],$A$31,tblData[Fiscal year],G$4,tblData[Standard line item],$A43) -> 2661
A44: Total assets | B44: =SUMIFS(tblData[Amount],tblData[Company],$A$31,tblData[Fiscal year],B$4,tblData[Standard line item],$A44) -> 13423.9 | C44: =SUMIFS(tblData[Amount],tblData[Company],$A$31,tblData[Fiscal year],C$4,tblData[Standard line item],$A44) -> 13592.1 | D44: =SUMIFS(tblData[Amount],tblData[Company],$A$31,tblData[Fiscal year],D$4,tblData[Standard line item],$A44) -> 13401.3 | E44: =SUMIFS(tblData[Amount],tblData[Company],$A$31,tblData[Fiscal year],E$4,tblData[Standard line item],$A44) -> 13865.3 | F44: =SUMIFS(tblData[Amount],tblData[Company],$A$31,tblData[Fiscal year],F$4,tblData[Standard line item],$A44) -> 14140.6 | G44: =SUMIFS(tblData[Amount],tblData[Company],$A$31,tblData[Fiscal year],G$4,tblData[Standard line item],$A44) -> 14539.4
A45: Total current liabilities | B45: =SUMIFS(tblData[Amount],tblData[Company],$A$31,tblData[Fiscal year],B$4,tblData[Standard line item],$A45) -> 1860.1 | C45: =SUMIFS(tblData[Amount],tblData[Company],$A$31,tblData[Fiscal year],C$4,tblData[Standard line item],$A45) -> 2198.2 | D45: =SUMIFS(tblData[Amount],tblData[Company],$A$31,tblData[Fiscal year],D$4,tblData[Standard line item],$A45) -> 1952.5 | E45: =SUMIFS(tblData[Amount],tblData[Company],$A$31,tblData[Fiscal year],E$4,tblData[Standard line item],$A45) -> 1960.8 | F45: =SUMIFS(tblData[Amount],tblData[Company],$A$31,tblData[Fiscal year],F$4,tblData[Standard line item],$A45) -> 2285.6 | G45: =SUMIFS(tblData[Amount],tblData[Company],$A$31,tblData[Fiscal year],G$4,tblData[Standard line item],$A45) -> 2053.8
...

Sheet YoY
A1: YoY: year-over-year change in the main lines
A2: Changes of 10% or more are highlighted. Red = decrease. Notes on the biggest changes are below the table.
A4: % change vs prior year | B4: 2021 | C4: 2022 | D4: 2023 | E4: 2024 | F4: 2025
A5: Loblaw
A6: Revenue | B6: =IFERROR(Model!C6/Model!B6-1,"") -> 0.0086504534 | C6: =IFERROR(Model!D6/Model!C6-1,"") -> 0.062704533 | D6: =IFERROR(Model!E6/Model!D6-1,"") -> 0.053536033 | E6: =IFERROR(Model!F6/Model!E6-1,"") -> 0.0099783299 | F6: =IFERROR(Model!G6/Model!F6-1,"") -> 0.062871114
A7: Cost of sales | B7: =IFERROR(Model!C7/Model!B7-1,"") -> -0.0078692988 | C7: =IFERROR(Model!D7/Model!C7-1,"") -> 0.057415743 | D7: =IFERROR(Model!E7/Model!D7-1,"") -> 0.050975914 | E7: =IFERROR(Model!F7/Model!E7-1,"") -> 0.019658204 | F7: =IFERROR(Model!G7/Model!F7-1,"") -> 0.06256055
A8: Gross profit | B8: =IFERROR(Model!C8/Model!B8-1,"") -> 0.046594534 | C8: =IFERROR(Model!D8/Model!C8-1,"") -> 0.074220151 | D8: =IFERROR(Model!E8/Model!D8-1,"") -> 0.059023142 | E8: =IFERROR(Model!F8/Model!E8-1,"") -> -0.010610916 | F8: =IFERROR(Model!G8/Model!F8-1,"") -> 0.063551898
A9: Operating income (EBIT) | B9: =IFERROR(Model!C9/Model!B9-1,"") -> 0.24186047 | C9: =IFERROR(Model!D9/Model!C9-1,"") -> 0.13789581 | D9: =IFERROR(Model!E9/Model!D9-1,"") -> 0.10831837 | E9: =IFERROR(Model!F9/Model!E9-1,"") -> -0.062095032 | F9: =IFERROR(Model!G9/Model!F9-1,"") -> 0.27345999
A10: Net finance costs | B10: =IFERROR(Model!C10/Model!B10-1,"") -> -0.3328841 | C10: =IFERROR(Model!D10/Model!C10-1,"") -> 0.37979798 | D10: =IFERROR(Model!E10/Model!D10-1,"") -> 0.17569546 | E10: =IFERROR(Model!F10/Model!E10-1,"") -> -0.1494396 | F10: =IFERROR(Model!G10/Model!F10-1,"") -> 0.086383602
A11: Earnings before income taxes | B11: =IFERROR(Model!C11/Model!B11-1,"") -> 0.50462107 | C11: =IFERROR(Model!D11/Model!C11-1,"") -> 0.088861589 | D11: =IFERROR(Model!E11/Model!D11-1,"") -> 0.091011659 | E11: =IFERROR(Model!F11/Model!E11-1,"") -> -0.037917959 | F11: =IFERROR(Model!G11/Model!F11-1,"") -> 0.31924042
A12: Income taxes | B12: =IFERROR(Model!C12/Model!B12-1,"") -> 0.081206497 | C12: =IFERROR(Model!D12/Model!C12-1,"") -> 0.42703863 | D12: =IFERROR(Model!E12/Model!D12-1,"") -> 0.073684211 | E12: =IFERROR(Model!F12/Model!E12-1,"") -> 0.023809524 | F12: =IFERROR(Model!G12/Model!F12-1,"") -> 0.47742818
A13: Net earnings | B13: =IFERROR(Model!C14/Model!B14-1,"") -> 0.65771812 | C13: =IFERROR(Model!D14/Model!C14-1,"") -> 0.0091093117 | D13: =IFERROR(Model!E14/Model!D14-1,"") -> 0.096790371 | E13: =IFERROR(Model!F14/Model!E14-1,"") -> 0.040237769 | F13: =IFERROR(Model!G14/Model!F14-1,"") -> 0.20351648
A14: Cash from operating activities | B14: =IFERROR(Model!C23/Model!B23-1,"") -> -0.070121364 | C14: =IFERROR(Model!D23/Model!C23-1,"") -> -0.014916097 | D14: =IFERROR(Model!E23/Model!D23-1,"") -> 0.18906414 | E14: =IFERROR(Model!F23/Model!E23-1,"") -> 0.026176158 | F14: =IFERROR(Model!G23/Model!F23-1,"") -> 0.079627715
A15: Capital expenditures | B15: =IFERROR(Model!C26/Model!B26-1,"") -> 0.020725389 | C15: =IFERROR(Model!D26/Model!C26-1,"") -> 0.32910321 | D15: =IFERROR(Model!E26/Model!D26-1,"") -> 0.31890516 | E15: =IFERROR(Model!F26/Model!E26-1,"") -> 0.061776062 | F15: =IFERROR(Model!G26/Model!F26-1,"") -> -0.062727273
A16: Free cash flow after leases | B16: =IFERROR(Model!C28/Model!B28-1,"") -> -0.12761715 | C16: =IFERROR(Model!D28/Model!C28-1,"") -> -0.16571429 | D16: =IFERROR(Model!E28/Model!D28-1,"") -> 0.14657534 | E16: =IFERROR(Model!F28/Model!E28-1,"") -> 0.0019912386 | F16: =IFERROR(Model!G28/Model!F28-1,"") -> 0.17130366
A18: Metro
A19: Revenue | B19: =IFERROR(Model!C32/Model!B32-1,"") -> 0.015863314 | C19: =IFERROR(Model!D32/Model!C32-1,"") -> 0.033140075 | D19: =IFERROR(Model!E32/Model!D32-1,"") -> 0.09718406 | E19: =IFERROR(Model!F32/Model!E32-1,"") -> 0.023899134 | F19: =IFERROR(Model!G32/Model!F32-1,"") -> 0.037078403
A20: Cost of sales | B20: =IFERROR(Model!C33/Model!B33-1,"") -> 0.014740873 | C20: =IFERROR(Model!D33/Model!C33-1,"") -> 0.032635594 | D20: =IFERROR(Model!E33/Model!D33-1,"") -> 0.1017371 | E20: =IFERROR(Model!F33/Model!E33-1,"") -> 0.023926837 | F20: =IFERROR(Model!G33/Model!F33-1,"") -> 0.034963558
A21: Gross profit | B21: =IFERROR(Model!C34/Model!B34-1,"") -> 0.020380814 | C21: =IFERROR(Model!D34/Model!C34-1,"") -> 0.035159243 | D21: =IFERROR(Model!E34/Model!D34-1,"") -> 0.079005101 | E21: =IFERROR(Model!F34/Model!E34-1,"") -> 0.023786194 | F21: =IFERROR(Model!G34/Model!F34-1,"") -> 0.045701433
A22: Operating income (EBIT) | B22: =IFERROR(Model!C35/Model!B35-1,"") -> 0.027106707 | C22: =IFERROR(Model!D35/Model!C35-1,"") -> 0.013554457 | D22: =IFERROR(Model!E35/Model!D35-1,"") -> 0.13624921 | E22: =IFERROR(Model!F35/Model!E35-1,"") -> -0.033647189 | F22: =IFERROR(Model!G35/Model!F35-1,"") -> 0.048860868
A23: Net finance costs | B23: =IFERROR(Model!C36/Model!B36-1,"") -> -0.024122807 | C23: =IFERROR(Model!D36/Model!C36-1,"") -> -0.11910112 | D23: =IFERROR(Model!E36/Model!D36-1,"") -> 0.042517007 | E23: =IFERROR(Model!F36/Model!E36-1,"") -> 0.18841762 | F23: =IFERROR(Model!G36/Model!F36-1,"") -> -0.013040494
A24: Earnings before income taxes | B24: =IFERROR(Model!C37/Model!B37-1,"") -> 0.033570045 | C24: =IFERROR(Model!D37/Model!C37-1,"") -> 0.029356652 | D24: =IFERROR(Model!E37/Model!D37-1,"") -> 0.14580444 | E24: =IFERROR(Model!F37/Model!E37-1,"") -> -0.054244212 | F24: =IFERROR(Model!G37/Model!F37-1,"") -> 0.056075514
A25: Income taxes | B25: =IFERROR(Model!C38/Model!B38-1,"") -> 0.024661341 | C25: =IFERROR(Model!D38/Model!C38-1,"") -> 0.030847458 | D25: =IFERROR(Model!E38/Model!D38-1,"") -> -0.0036172312 | E25: =IFERROR(Model!F38/Model!E38-1,"") -> 0.050825083 | F25: =IFERROR(Model!G38/Model!F38-1,"") -> -0.055590452
A26: Net earnings | B26: =IFERROR(Model!C40/Model!B40-1,"") -> 0.036790558 | C26: =IFERROR(Model!D40/Model!C40-1,"") -> 0.028824028 | D26: =IFERROR(Model!E40/Model!D40-1,"") -> 0.1992937 | E26: =IFERROR(Model!F40/Model!E40-1,"") -> -0.085492737 | F26: =IFERROR(Model!G40/Model!F40-1,"") -> 0.094236342
A27: Cash from operating activities | B27: =IFERROR(Model!C49/Model!B49-1,"") -> 0.074079099 | C27: =IFERROR(Model!D49/Model!C49-1,"") -> -0.076991095 | D27: =IFERROR(Model!E49/Model!D49-1,"") -> 0.069864513 | E27: =IFERROR(Model!F49/Model!E49-1,"") -> 0.07259354 | F27: =IFERROR(Model!G49/Model!F49-1,"") -> 0.02856291
A28: Capital expenditures | B28: =IFERROR(Model!C52/Model!B52-1,"") -> 0.17348737 | C28: =IFERROR(Model!D52/Model!C52-1,"") -> 0.03620891 | D28: =IFERROR(Model!E52/Model!D52-1,"") -> 0.094847021 | E28: =IFERROR(Model!F52/Model!E52-1,"") -> -0.14737461 | F28: =IFERROR(Model!G52/Model!F52-1,"") -> -0.11919959
A29: Free cash flow after leases | B29: =IFERROR(Model!C54/Model!B54-1,"") -> 0.01773399 | C29: =IFERROR(Model!D54/Model!C54-1,"") -> -0.20840824 | D29: =IFERROR(Model!E54/Model!D54-1,"") -> 0.073549965 | E29: =IFERROR(Model!F54/Model!E54-1,"") -> 0.34987795 | F29: =IFERROR(Model!G54/Model!F54-1,"") -> 0.12429174
A31: Empire
A32: Revenue | B32: =IFERROR(Model!C58/Model!B58-1,"") -> 0.063189686 | C32: =IFERROR(Model!D58/Model!C58-1,"") -> 0.067004383 | D32: =IFERROR(Model!E58/Model!D58-1,"") -> 0.010466674 | E32: =IFERROR(Model!F58/Model!E58-1,"") -> 0.0083633822 | F32: =IFERROR(Model!G58/Model!F58-1,"") -> 0.017700843
A33: Cost of sales | B33: =IFERROR(Model!C59/Model!B59-1,"") -> 0.055830899 | C33: =IFERROR(Model!D59/Model!C59-1,"") -> 0.068047843 | D33: =IFERROR(Model!E59/Model!D59-1,"") -> 0.0081190257 | E33: =IFERROR(Model!F59/Model!E59-1,"") -> -0.0010315004 | F33: =IFERROR(Model!G59/Model!F59-1,"") -> 0.010281529
A34: Gross profit | B34: =IFERROR(Model!C60/Model!B60-1,"") -> 0.085327062 | C34: =IFERROR(Model!D60/Model!C60-1,"") -> 0.063950662 | D34: =IFERROR(Model!E60/Model!D60-1,"") -> 0.017363604 | E34: =IFERROR(Model!F60/Model!E60-1,"") -> 0.035712911 | F34: =IFERROR(Model!G60/Model!F60-1,"") -> 0.038533019
